Workbook

Sheet Faculty List
B1: Fintech (Digital Transformation in Finance) (A) | C1: Fintech (Digital Transformation in Finance) (B) | D1: Behavioural Economics and Decision-Making (A) | E1: Behavioural Economics and Decision-Making (B) | F1: The Art, Craft, and Science of Management: Learning through Classics and Best Collections (A) | G1: The Art, Craft, and Science of Management: Learning through Classics and Best Collections (B) | H1: Workplace Happiness: Science & Practice (A) | I1: Workplace Happiness: Science & Practice (B) | J1: Leadership Excellence Through Values : Wisdom from the Mahabharata | K1: Film & the Firm: Visual Culture in Business Contexts (A) | L1: Film & the Firm: Visual Culture in Business Contexts (B) | M1: Strategic HRM | N1: Strategic Career Management (A) | O1: Strategic Career Management (B) | P1: AI AND STRATEGY | Q1: Employer Branding | R1: AI Applications in Marketing (A) | S1: AI Applications in Marketing (B) | T1: SPORTS ANALYTICS (A) | U1: SPORTS ANALYTICS (B) | V1: Customer Success Management | W1: Entrepreneurial Marketing | X1: Industry 4.0 in Transport Sector
A2: 1 | B2: Prof Shumaila Fatima | C2: Prof Shumaila Fatima | D2: Prof. Amarendu Nandy | E2: Prof. Amarendu Nandy | F2: Ambuj B. Anand,Manish Kumar | G2: Ambuj B. Anand,Manish Kumar | H2: Prof. Allen Joshua George | I2: Prof. Allen Joshua George | J2: Dr. Radha Yadav | K2: Prof. Vikas Pathe | L2: Prof. Vikas Pathe | M2: Prof. Rameshwar Shivadas Ture | N2: Prof. Aditya Agrawal | O2: Prof. Aditya Agrawal | P2: Prof Jang Bahadur Singh | Q2: Prof. Radha Yadav | R2: Prof. Ankur Jha | S2: Prof. Ankur Jha | T2: Prof. R. Vivekananda | U2: Prof. R. Vivekananda | V2: Prof. Shilpi Saxena | W2: Prof. Rohit Kumar | X2: Prof. Krishna Kumar Dadsena
A3: 2 | B3: Prof Shumaila Fatima | C3: Prof Shumaila Fatima | D3: Prof. Amarendu Nandy | E3: Prof. Amarendu Nandy | F3: Ambuj B. Anand,Manish Kumar | G3: Ambuj B. Anand,Manish Kumar | H3: Prof. Tanusree Dutta | I3: Prof. Tanusree Dutta | J3: Dr. Radha Yadav | K3: Prof. Vikas Pathe | L3: Prof. Vikas Pathe | M3: Prof. Rameshwar Shivadas Ture | N3: Prof. Aditya Agrawal | O3: Prof. Aditya Agrawal | P3: Prof Jang Bahadur Singh | Q3: Prof. Radha Yadav | R3: Prof. Ankur Jha | S3: Prof. Ankur Jha | T3: Prof. R. Vivekananda | U3: Prof. R. Vivekananda | V3: Prof. Shilpi Saxena | W3: Prof. Rohit Kumar | X3: Prof. Krishna Kumar Dadsena
A4: 3 | B4: Prof Shumaila Fatima | C4: Prof Shumaila Fatima | D4: Prof. Amarendu Nandy | E4: Prof. Amarendu Nandy | F4: Ambuj B. Anand,Manish Kumar | G4: Ambuj B. Anand,Manish Kumar | H4: Prof. Allen Joshua George | I4: Prof. Allen Joshua George | J4: Dr. Radha Yadav | K4: Prof. Vikas Pathe | L4: Prof. Vikas Pathe | M4: Prof. Rameshwar Shivadas Ture | N4: Prof. Rohit Kumar | O4: Prof. Rohit Kumar | P4: Prof Jang Bahadur Singh | Q4: Prof. Radha Yadav | R4: Prof. Ankur Jha | S4: Prof. Ankur Jha | T4: Prof. R. Vivekananda | U4: Prof. R. Vivekananda | V4: Prof. Shilpi Saxena | W4: Prof. Rohit Kumar | X4: Prof. Krishna Kumar Dadsena
A5: 4 | B5: Prof Shumaila Fatima | C5: Prof Shumaila Fatima | D5: Prof. Amarendu Nandy | E5: Prof. Amarendu Nandy | F5: Ambuj B. Anand,Manish Kumar | G5: Ambuj B. Anand,Manish Kumar | H5: Prof. Allen Joshua George | I5: Prof. Allen Joshua George | J5: Dr. Radha Yadav | K5: Prof. Vikas Pathe | L5: Prof. Vikas Pathe | M5: Prof. Rameshwar Shivadas Ture | N5: Prof. Aditya Agrawal | O5: Prof. Aditya Agrawal | P5: Prof Jang Bahadur Singh | Q5: Prof. Radha Yadav | R5: Prof. Ankur Jha | S5: Prof. Ankur Jha | T5: Prof. R. Vivekananda | U5: Prof. R. Vivekananda | V5: Prof. Shilpi Saxena | W5: Prof. Rohit Kumar | X5: Prof. Shailabh Kumar Sahu
A6: 5 | B6: Prof Shumaila Fatima | C6: Prof Shumaila Fatima | D6: Prof. Amarendu Nandy | E6: Prof. Amarendu Nandy | F6: Ambuj B. Anand,Manish Kumar | G6: Ambuj B. Anand,Manish Kumar | H6: Prof. Allen Joshua George | I6: Prof. Allen Joshua George | J6: Dr. Radha Yadav | K6: Prof. Manish Kumar | L6: Prof. Manish Kumar | M6: Prof. Rameshwar Shivadas Ture | N6: Prof. Aditya Agrawal | O6: Prof. Aditya Agrawal | P6: Prof Jang Bahadur Singh | Q6: Prof. Radha Yadav | R6: Prof. Ankur Jha | S6: Prof. Ankur Jha | T6: Prof. R. Vivekananda | U6: Prof. R. Vivekananda | V6: Prof. Shilpi Saxena | W6: Prof. Rohit Kumar | X6: Prof. Shailabh Kumar Sahu
A7: 6 | B7: Prof Shumaila Fatima | C7: Prof Shumaila Fatima | D7: Prof. Tanusree Dutta | E7: Prof. Tanusree Dutta | F7: Ambuj B. Anand,Manish Kumar | G7: Ambuj B. Anand,Manish Kumar | H7: Prof. Tanusree Dutta | I7: Prof. Tanusree Dutta | J7: Dr. Radha Yadav | K7: Prof. Manish Kumar | L7: Prof. Manish Kumar | M7: Prof. Rameshwar Shivadas Ture | N7: Prof. Aditya Agrawal | O7: Prof. Aditya Agrawal | P7: Prof Jang Bahadur Singh | Q7: Prof. Radha Yadav | R7: Prof. Shweta Jha | S7: Prof. Shweta Jha | T7: Prof. R. Vivekananda | U7: Prof. R. Vivekananda | V7: Prof. Shilpi Saxena | W7: Prof. Satyam | X7: Prof. Shailabh Kumar Sahu
A8: 7 | B8: Prof Shumaila Fatima | C8: Prof Shumaila Fatima | D8: Prof. Poonam Prasad | E8: Prof. Poonam Prasad | F8: Ambuj B. Anand,Manish Kumar | G8: Ambuj B. Anand,Manish Kumar | H8: Prof. Allen Joshua George | I8: Prof. Allen Joshua George | J8: Dr. Radha Yadav | K8: Prof. Gaurav M Marathe | L8: Prof. Gaurav M Marathe | M8: Prof. Rameshwar Shivadas Ture | N8: Prof. Aditya Agrawal | O8: Prof. Aditya Agrawal | P8: Prof Jang Bahadur Singh | Q8: Prof. Radha Yadav | R8: Prof. Shweta Jha | S8: Prof. Shweta Jha | T8: Prof. R. Vivekananda | U8: Prof. R. Vivekananda | V8: Prof. Shilpi Saxena | W8: Prof. Satyam | X8: Prof. Shailabh Kumar Sahu
A9: 8 | B9: Prof Shumaila Fatima | C9: Prof Shumaila Fatima | D9: Prof. Poonam Prasad | E9: Prof. Poonam Prasad | F9: Ambuj B. Anand,Manish Kumar | G9: Ambuj B. Anand,Manish Kumar | H9: Prof. Allen Joshua George | I9: Prof. Allen Joshua George | J9: Dr. Radha Yadav | K9: Prof. Gaurav M Marathe | L9: Prof. Gaurav M Marathe | M9: Prof. Rameshwar Shivadas Ture | N9: Prof. Aditya Agrawal | O9: Prof. Aditya Agrawal | P9: Prof Jang Bahadur Singh | Q9: Prof. Radha Yadav | R9: Prof. Shweta Jha | S9: Prof. Shweta Jha | T9: Prof. R. Vivekananda | U9: Prof. R. Vivekananda | V9: Prof. Shilpi Saxena | W9: Prof. Satyam | X9: Prof. Sachin Bajaj
A10: 9 | B10: Prof Shumaila Fatima | C10: Prof Shumaila Fatima | D10: Prof. Poonam Prasad | E10: Prof. Poonam Prasad | F10: Ambuj B. Anand,Manish Kumar | G10: Ambuj B. Anand,Manish Kumar | H10: Prof. Tanusree Dutta | I10: Prof. Tanusree Dutta | J10: Dr. Radha Yadav | K10: Prof. Manish Kumar | L10: Prof. Manish Kumar | M10: Prof. Rameshwar Shivadas Ture | N10: Prof. Aditya Agrawal | O10: Prof. Aditya Agrawal | P10: Prof. Santosh K Prusty | Q10: Prof. Radha Yadav | R10: Prof. Shweta Jha | S10: Prof. Shweta Jha | T10: Prof. R. Vivekananda | U10: Prof. R. Vivekananda | V10: Prof. Shilpi Saxena | W10: Prof. Satyam | X10: Prof. Sachin Bajaj
A11: 10 | B11: Guest Lecture | C11: Guest Lecture | D11: Prof. Tanusree Dutta | E11: Prof. Tanusree Dutta | F11: Ambuj B. Anand,Manish Kumar | G11: Ambuj B. Anand,Manish Kumar | H11: Prof. Allen Joshua George | I11: Prof. Allen Joshua George | J11: Dr. Prasant Maurya | K11: Prof. Manish Kumar | L11: Prof. Manish Kumar | M11: Mr. Vaibhav Goel | N11: Prof. Rohit Kumar | O11: Prof. Rohit Kumar | P11: Prof. Santosh K Prusty | Q11: Prof. Radha Yadav | R11: Prof. Shweta Jha | S11: Prof. Shweta Jha | T11: Prof. R. Vivekananda | U11: Prof. R. Vivekananda | V11: Prof. Shilpi Saxena | W11: Prof. Satyam | X11: Prof. Sachin Bajaj
A12: 11 | B12: Prof Gautam Pal | C12: Prof Gautam Pal | D12: Prof. Amarendu Nandy | E12: Prof. Amarendu Nandy | F12: Ambuj B. Anand,Manish Kumar | G12: Ambuj B. Anand,Manish Kumar | H12: Prof. Tanusree Dutta | I12: Prof. Tanusree Dutta | J12: Dr. Prasant Maurya | K12: Guest Faculty | L12: Guest Faculty | M12: Mr. Vaibhav Goel | N12: Prof. Rohit Kumar | O12: Prof. Rohit Kumar | P12: Prof. Santosh K Prusty | Q12: Prof. Shweta Jha | R12: Dr. Charu Jain | S12: Dr. Charu Jain | T12: Prof. R. Vivekananda | U12: Prof. R. Vivekananda | V12: Prof. Shilpi Saxena | W12: Mr. Avnish Anand | X12: Prof. Sachin Bajaj
A13: 12 | B13: Prof Gautam Pal | C13: Prof Gautam Pal | D13: Prof. Poonam Prasad | E13: Prof. Poonam Prasad | F13: Ambuj B. Anand,Manish Kumar | G13: Ambuj B. Anand,Manish Kumar | H13: Prof. Allen Joshua George | I13: Prof. Allen Joshua George | J13: Dr. Prasant Maurya | K13: Guest Faculty | L13: Guest Faculty | M13: Mr. Vaibhav Goel | N13: Prof. Rohit Kumar | O13: Prof. Rohit Kumar | P13: Prof. Santosh K Prusty | Q13: Prof. Shweta Jha | R13: Dr. Charu Jain | S13: Dr. Charu Jain | T13: Prof. R. Vivekananda | U13: Prof. R. Vivekananda | V13: Prof. Shilpi Saxena | W13: Mr. Avnish Anand | X13: Prof. Sachin Bajaj
... A21: 20 | B21: Prof Gautam Pal | C21: Prof Gautam Pal | D21: Prof. Amarendu Nandy | E21: Prof. Amarendu Nandy | F21: Guest Faculty | G21: Guest Faculty | H21: Guest Faculty | I21: Guest Faculty | J21: Dr. Radha Yadav | K21: Prof. George Joseph | L21: Prof. George Joseph | M21: Prof. Rameshwar Shivadas Ture | N21: Prof. Aditya Agrawal | O21: Prof. Aditya Agrawal | P21: Prof. Santosh K Prusty | Q21: Prof. Shweta Jha | R21: Ms.Deborah T. Joy | S21: Ms.Deborah T. Joy | T21: Prof. Ambuj Anand | U21: Prof. Ambuj Anand | V21: Mr. Nishant Gaurav | W21: Prof. Satyam | X21: Prof. Krishna Kumar Dadsena

Sheet Exam
A1: Day | B1: Slot | C1: Exam
A2: 17 | B2: 1 | F2: Fintech | G2: Art
B3: 2 | F3: BEDM | G3: I4TS
B4: 3 | F4: WH | G4: SA
A5: 18 | B5: 1 | C5: AIS | D5: 46307 | F5: Film&Firm | G5: CSM
B6: 2 | C6: Fintech | D6: 1:30-3:30 | F6: AIS | G6: SCM
B7: 3 | D7: 46149 | F7: EB | G7: SHRM
A8: 19 | B8: 1 | C8: AIAM | F8: EM | G8: AIAM
B9: 2 | C9: Film&Firm | F9: LETV
B10: 3
A11: 20 | B11: 1 | C11: SHRM
B12: 2 | C12: BEDM
B13: 3
A14: 21 | B14: 1 | C14: Art
B15: 2 | C15: CSM
B16: 3 | C16: WH
A17: 23 | B17: 1 | C17: SA
B18: 2 | C18: LETV
B19: 3 | C19: EM
A20: 24 | B20: 1 | C20: SCM
B21: 2 | C21: I4TS
B22: 3 | C22: EB

Sheet Course Details
A1: Term V Course Offering - MBA/MBA-BA/MBA-HRM (AY: 2025-26)
A2: SL No. | B2: Course Code | C2: Course Name | D2: Faculty Name
A3: 1 | B3: FAISE01-A | C3: Fintech (Digital Transformation in Finance) (A) | D3: Prof Shumaila Fatima, Prof Gautam Pal
A4: 2 | B4: FAISE01-B | C4: Fintech (Digital Transformation in Finance) (B) | D4: Prof Shumaila Fatima, Prof Gautam Pal
A5: 3 | B5: HRECFAE01-A | C5: Behavioural Economics and Decision-Making (A) | D5: Prof. Tanusree Dutta, Prof. Amarendu Nandy, External Expert
A6: 4 | B6: HRECFAE01-B | C6: Behavioural Economics and Decision-Making (B) | D6: Prof. Tanusree Dutta, Prof. Amarendu Nandy, External Expert
A7: 5 | B7: HRISE01-A | C7: The Art, Craft, and Science of Management: Learning through Classics and Best Collections (A) | D7: Ambuj B. Anand, Manish Kumar, Guest Faculty
A8: 6 | B8: HRISE01-B | C8: The Art, Craft, and Science of Management: Learning through Classics and Best Collections (B) | D8: Ambuj B. Anand, Manish Kumar, Guest Faculty
A9: 7 | B9: HRLAE01-A | C9: Workplace Happiness: Science & Practice (A) | D9: Prof. Tanusree Dutta, Prof. Allen Joshua George, Guest Faculty
A10: 8 | B10: HRLAE01-B | C10: Workplace Happiness: Science & Practice (B) | D10: Prof. Tanusree Dutta, Prof. Allen Joshua George, Guest Faculty
A11: 9 | B11: HRLAE03 | C11: Leadership Excellence Through Values : Wisdom from the Mahabharata | D11: Dr. Radha Yadav, Dr. Prasant Maurya, Dr. Ashish Pandey
A12: 10 | B12: HRLAISE01-A | C12: Film and the Firm: Visual Culture in Business Contexts (A) | D12: Prof. Vikas Pathe, Prof. Ambuj B. Anand, Prof. Manish Kumar, Prof. Gaurav M Marathe, Prof. George Joseph, Guest Faculty
A13: 11 | B13: HRLAISE01-B | C13: Film and the Firm: Visual Culture in Business Contexts (B) | D13: Prof. Vikas Pathe, Prof. Ambuj B. Anand, Prof. Manish Kumar, Prof. Gaurav M Marathe, Prof. George Joseph, Guest Faculty
A14: 12 | B14: HRSEE01 | C14: Strategic HRM | D14: Prof. Rameshwar Shivadas Ture, Mr. Vaibhav Goel
... A25: 23 | B25: OMISE01 | C25: Industry 4.0 in Transport Sector | D25: Prof.Krishna Kumar Dadsena, Prof. Sachin Bajaj, Prof. Reema Jogani, Prof. Shailabh Kumar Sahu

Sheet Schedule
D1: Term 6 Schedule - Dec 29 - Jan 4
A2: Week 1 | C2: 9.00AM - 10.30AM | D2: 10.45AM - 12.15PM | E2: 12.30PM - 2.00PM | F2: 3.00PM - 4.30PM | G2: 4.45PM - 6.15PM | H2: 6.30PM - 8.00PM | I2: 8.15PM - 9.45PM | K2: AIAM-A | L2: =COUNTIF($A$1:$I$950,K2 ) -> 20
A3: 46020 | B3: Mon | C3: LETV | D3: Fintech-B | F3: AIS | G3: EM | H3: AIAM-A | I3: AIS | K3: AIAM-B | L3: =COUNTIF($A$1:$I$950,K3 ) -> 20
C4: Dr. Radha Yadav | D4: Prof Shumaila Fatima | F4: Prof Jang Bahadur Singh | G4: Prof. Rohit Kumar | H4: Prof. Ankur Jha | I4: Prof Jang Bahadur Singh | K4: BEDM-A | L4: =COUNTIF($A$1:$I$950,K4 ) -> 20
D5: Art-A | E5: EB | G5: Art-B | H5: I4TS | K5: BEDM-B | L5: =COUNTIF($A$1:$I$950,K5 ) -> 20
D6: Ambuj Anand,Manish Kumar | E6: Prof. Radha Yadav | G6: Ambuj Anand,Manish Kumar | H6: Prof. Krishna Kumar Dadsena | K6: EM | L6: =COUNTIF($A$1:$I$950,K6 ) -> 20
A7: =A3+1 -> 46021 | B7: Tue | C7: AIS | D7: Fintech-B | E7: AIS | G7: Film&Firm-B | H7: Film&Firm-B | I7: AIAM-B | K7: Fintech-A | L7: =COUNTIF($A$1:$I$950,K7 ) -> 19
C8: Prof Jang Bahadur Singh | D8: Prof Shumaila Fatima | E8: Prof Jang Bahadur Singh | G8: Prof. Vikas Pathe | H8: Prof. Vikas Pathe | I8: Prof. Ankur Jha | K8: Fintech-B | L8: =COUNTIF($A$1:$I$950,K8 ) -> 19
D9: Art-A | F9: EB | G9: SCM-B | H9: SCM-B | I9: SHRM | K9: LETV | L9: =COUNTIF($A$1:$I$950,K9 ) -> 20
D10: Ambuj Anand,Manish Kumar | F10: Prof. Radha Yadav | G10: Prof. Aditya Agrawal | H10: Prof. Aditya Agrawal | I10: Prof. Rameshwar Shivadas Ture | K10: SA-B | L10: =COUNTIF($A$1:$I$950,K10 ) -> 20
A11: =A7+1 -> 46022 | B11: Wed | C11: LETV | D11: Fintech-B | E11: CSM | F11: CSM | G11: EM | K11: SCM-A | L11: =COUNTIF($A$1:$I$950,K11 ) -> 20
C12: Dr. Radha Yadav | D12: Prof Shumaila Fatima | E12: Prof. Shilpi Saxena | F12: Prof. Shilpi Saxena | G12: Prof. Rohit Kumar | K12: SCM-B | L12: =COUNTIF($A$1:$I$950,K12 ) -> 20
D13: Art-A | E13: WH-B | F13: WH-B | G13: Art-B | K13: WH-A | L13: =COUNTIF($A$1:$I$950,K13 ) -> 18
D14: Ambuj Anand,Manish Kumar | E14: Prof. Allen Joshua George | F14: Prof. Allen Joshua George | G14: Ambuj Anand,Manish Kumar | K14: WH-B | L14: =COUNTIF($A$1:$I$950,K14 ) -> 18
A15: =A11+1 -> 46023 | B15: Thurs | D15: EM | E15: CSM | F15: Fintech-A | G15: Film&Firm-B | H15: Film&Firm-B | I15: AIAM-A | K15: I4TS | L15: =COUNTIF($A$1:$I$950,K15 ) -> 16
D16: Prof. Rohit Kumar | E16: Prof. Shilpi Saxena | F16: Prof Shumaila Fatima | G16: Prof. Vikas Pathe | H16: Prof. Vikas Pathe | I16: Prof. Ankur Jha | K16: SA-A | L16: =COUNTIF($A$1:$I$950,K16 ) -> 20
D17: Art-B | E17: WH-B | F17: WH-A | G17: SCM-B | H17: SCM-B | I17: I4TS | K17: EB | L17: =COUNTIF($A$1:$I$950,K17 ) -> 20
D18: Ambuj Anand,Manish Kumar | E18: Prof. Allen Joshua George | F18: Prof. Allen Joshua George | G18: Prof. Rohit Kumar | H18: Prof. Aditya Agrawal | I18: Prof. Krishna Kumar Dadsena | K18: AIS | L18: =COUNTIF($A$1:$I$950,K18 ) -> 20
A19: =A15+1 -> 46024 | B19: Fri | C19: LETV | D19: Fintech-A | E19: AIAM-B | F19: Fintech-A | G19: Film&Firm-A | H19: Film&Firm-A | I19: AIAM-B | K19: Art-A | L19: =COUNTIF($A$1:$I$950,K19 ) -> 18
C20: Dr. Radha Yadav | D20: Prof Shumaila Fatima | E20: Prof. Ankur Jha | F20: Prof Shumaila Fatima | G20: Prof. Vikas Pathe | H20: Prof. Vikas Pathe | I20: Prof. Ankur Jha | K20: Art-B | L20: =COUNTIF($A$1:$I$950,K20 ) -> 18
D21: WH-A | E21: SHRM | F21: WH-A | G21: SCM-A | H21: SCM-A | I21: SHRM | K21: SHRM | L21: =COUNTIF($A$1:$I$950,K21 ) -> 20
D22: Prof. Allen Joshua George | E22: Prof. Rameshwar Shivadas Ture | F22: Prof. Allen Joshua George | G22: Prof. Aditya Agrawal | H22: Prof. Aditya Agrawal | I22: Prof. Rameshwar Shivadas Ture | K22: Film&Firm-A | L22: =COUNTIF($A$1:$I$950,K22 ) -> 20
A23: =A19+1 -> 46025 | B23: Sat | D23: Film&Firm-A | E23: Film&Firm-A | F23: AIAM-A | K23: Film&Firm-B | L23: =COUNTIF($A$1:$I$950,K23 ) -> 20
D24: Prof. Vikas Pathe | E24: Prof. Vikas Pathe | F24: Prof. Ankur Jha | K24: CSM | L24: =COUNTIF($A$1:$I$950,K24 ) -> 20
D25: SCM-A | E25: SCM-A | F25: I4TS
D26: Prof. Rohit Kumar | E26: Prof. Aditya Agrawal | F26: Prof. Krishna Kumar Dadsena
A27: =A23+1 -> 46026 | B27: Sun
D32: Term 6 Schedule - Jan 5 - Jan 11
A33: Week 2 | C33: 9.00AM - 10.30AM | D33: 10.45AM - 12.15PM | E33: 12.30PM - 2.00PM | F33: 3.00PM - 4.30PM | G33: 4.45PM - 6.15PM | H33: 6.30PM - 8.00PM | I33: 8.15PM - 9.45PM
A34: =A27+1 -> 46027 | B34: Mon | C34: AIAM-A | D34: Fintech-B | E34: BEDM-A | F34: Fintech-A | G34: EM | H34: BEDM-B
C35: Prof. Ankur Jha | D35: Prof Shumaila Fatima | E35: Prof. Amarendu Nandy | F35: Prof Shumaila Fatima | G35: Prof. Rohit Kumar | H35: Prof. Amarendu Nandy
C36: I4TS | D36: Art-A | E36: EB | F36: WH-A | G36: Art-B
C37: Prof. Krishna Kumar Dadsena | D37: Ambuj Anand,Manish Kumar | E37: Prof. Radha Yadav | F37: Prof. Allen Joshua George | G37: Ambuj Anand,Manish Kumar
A38: =A34+1 -> 46028 | B38: Tue | C38: BEDM-B | D38: Fintech-B | E38: BEDM-A | F38: Fintech-A | G38: Film&Firm-B | H38: Film&Firm-B | I38: AIAM-A
C39: Prof. Amarendu Nandy | D39: Prof Shumaila Fatima | E39: Prof. Amarendu Nandy | F39: Prof Shumaila Fatima | G39: Prof. Manish Kumar | H39: Prof. Manish Kumar | I39: Prof. Ankur Jha
D40: Art-A | E40: EB | F40: WH-A | G40: SCM-B | H40: SCM-B
D41: Ambuj Anand,Manish Kumar | E41: Prof. Radha Yadav | F41: Prof. Tanusree Dutta | G41: Prof. Aditya Agrawal | H41: Prof. Aditya Agrawal
A42: =A38+1 -> 46029 | B42: Wed | C42: LETV | D42: Fintech-B | E42: CSM | F42: CSM | G42: Film&Firm-A | H42: Film&Firm-A
C43: Dr. Radha Yadav | D43: Prof Shumaila Fatima | E43: Prof. Shilpi Saxena | F43: Prof. Shilpi Saxena | G43: Prof. Manish Kumar | H43: Prof. Manish Kumar
D44: Art-A | E44: WH-B | F44: WH-B | G44: SCM-A | H44: SCM-A | I44: SHRM
...

Sheet Rescheduling Master
A1: INDEX | B1: Fintech-A | C1: Fintech-B | D1: BEDM-A | E1: BEDM-B | F1: Art-A | G1: Art-B | H1: WH-A | I1: WH-B | J1: LETV | K1: Film&Firm-A | L1: Film&Firm-B | M1: SHRM | N1: SCM-A | O1: SCM-B | P1: AIS | Q1: EB | R1: AIAM-A | S1: AIAM-B | T1: SA-A | U1: SA-B | V1: CSM | W1: EM | X1: I4TS
A2: Fintech-A | C2: {=TRANSPOSE(B3:B$24)} -> 0 | D2: 10 | E2: 7 | F2: 13 | G2: 0 | H2: 0 | I2: 5 | J2: 4 | K2: 10 | L2: 8 | M2: 0 | N2: 3 | O2: 11 | P2: 11 | Q2: 7 | R2: 16 | S2: 13 | T2: 17 | U2: 9 | V2: 8 | W2: 10 | X2: 14
A3: Fintech-B | B3: 0 | D3: {=TRANSPOSE(C4:C$24)} -> 10 | E3: 9 | F3: 0 | G3: 0 | H3: 4 | I3: 7 | J3: 6 | K3: 10 | L3: 11 | M3: 3 | N3: 6 | O3: 5 | P3: 10 | Q3: 4 | R3: 13 | S3: 13 | T3: 5 | U3: 19 | V3: 14 | W3: 14 | X3: 11
A4: BEDM-A | B4: 10 | C4: 10 | E4: {=TRANSPOSE(D5:D$24)} -> 0 | F4: 4 | G4: 2 | H4: 2 | I4: 13 | J4: 4 | K4: 3 | L4: 5 | M4: 2 | N4: 7 | O4: 5 | P4: 8 | Q4: 0 | R4: 5 | S4: 6 | T4: 5 | U4: 5 | V4: 5 | W4: 12 | X4: 5
A5: BEDM-B | B5: 7 | C5: 9 | D5: 0 | F5: {=TRANSPOSE(E6:E$24)} -> 3 | G5: 2 | H5: 0 | I5: 2 | J5: 5 | K5: 10 | L5: 1 | M5: 3 | N5: 2 | O5: 4 | P5: 0 | Q5: 9 | R5: 13 | S5: 8 | T5: 15 | U5: 9 | V5: 6 | W5: 13 | X5: 9
A6: Art-A | B6: 13 | C6: 0 | D6: 4 | E6: 3 | G6: {=TRANSPOSE(F7:F$24)} -> 0 | H6: 7 | I6: 6 | J6: 7 | K6: 14 | L6: 7 | M6: 19 | N6: 8 | O6: 8 | P6: 7 | Q6: 7 | R6: 6 | S6: 7 | T6: 10 | U6: 3 | V6: 2 | W6: 11 | X6: 7
A7: Art-B | B7: 0 | C7: 0 | D7: 2 | E7: 2 | F7: 0 | H7: {=TRANSPOSE(G8:G$24)} -> 8 | I7: 9 | J7: 6 | K7: 9 | L7: 7 | M7: 16 | N7: 5 | O7: 5 | P7: 8 | Q7: 13 | R7: 4 | S7: 3 | T7: 3 | U7: 0 | V7: 1 | W7: 0 | X7: 5
A8: WH-A | B8: 0 | C8: 4 | D8: 2 | E8: 0 | F8: 7 | G8: 8 | I8: {=TRANSPOSE(H9:H$24)} -> 0 | J8: 13 | K8: 7 | L8: 11 | M8: 10 | N8: 18 | O8: 10 | P8: 3 | Q8: 9 | R8: 10 | S8: 4 | T8: 4 | U8: 5 | V8: 8 | W8: 4 | X8: 5
A9: WH-B | B9: 5 | C9: 7 | D9: 13 | E9: 2 | F9: 6 | G9: 9 | H9: 0 | J9: {=TRANSPOSE(I10:I$24)} -> 12 | K9: 12 | L9: 6 | M9: 10 | N9: 8 | O9: 9 | P9: 8 | Q9: 2 | R9: 6 | S9: 3 | T9: 8 | U9: 0 | V9: 0 | W9: 8 | X9: 4
A10: LETV | B10: 4 | C10: 6 | D10: 4 | E10: 5 | F10: 7 | G10: 6 | H10: 13 | I10: 12 | K10: {=TRANSPOSE(J11:J$24)} -> 9 | L10: 14 | M10: 6 | N10: 4 | O10: 9 | P10: 10 | Q10: 7 | R10: 6 | S10: 3 | T10: 2 | U10: 5 | V10: 5 | W10: 9 | X10: 11
A11: Film&Firm-A | B11: 10 | C11: 10 | D11: 3 | E11: 10 | F11: 14 | G11: 9 | H11: 7 | I11: 12 | J11: 9 | L11: {=TRANSPOSE(K12:K$24)} -> 0 | M11: 11 | N11: 0 | O11: 0 | P11: 8 | Q11: 7 | R11: 6 | S11: 11 | T11: 14 | U11: 15 | V11: 7 | W11: 3 | X11: 4
A12: Film&Firm-B | B12: 8 | C12: 11 | D12: 5 | E12: 1 | F12: 7 | G12: 7 | H12: 11 | I12: 6 | J12: 14 | K12: 0 | M12: {=TRANSPOSE(L13:L$24)} -> 4 | N12: 24 | O12: 0 | P12: 11 | Q12: 3 | R12: 9 | S12: 4 | T12: 9 | U12: 7 | V12: 10 | W12: 4 | X12: 5
A13: SHRM | B13: 0 | C13: 3 | D13: 2 | E13: 3 | F13: 19 | G13: 16 | H13: 10 | I13: 10 | J13: 6 | K13: 11 | L13: 4 | N13: {=TRANSPOSE(M14:M$24)} -> 11 | O13: 20 | P13: 8 | Q13: 21 | R13: 7 | S13: 0 | T13: 3 | U13: 0 | V13: 4 | W13: 10 | X13: 2
A14: SCM-A | B14: 3 | C14: 6 | D14: 7 | E14: 2 | F14: 8 | G14: 5 | H14: 18 | I14: 8 | J14: 4 | K14: 0 | L14: 24 | M14: 11 | O14: {=TRANSPOSE(N15:N$24)} -> 0 | P14: 7 | Q14: 6 | R14: 11 | S14: 7 | T14: 9 | U14: 7 | V14: 4 | W14: 15 | X14: 10
A15: SCM-B | B15: 11 | C15: 5 | D15: 5 | E15: 4 | F15: 8 | G15: 5 | H15: 10 | I15: 9 | J15: 9 | K15: 0 | L15: 0 | M15: 20 | N15: 0 | P15: {=TRANSPOSE(O16:O$24)} -> 8 | Q15: 11 | R15: 16 | S15: 5 | T15: 8 | U15: 7 | V15: 11 | W15: 15 | X15: 5
A16: AIS | B16: 11 | C16: 10 | D16: 8 | E16: 0 | F16: 7 | G16: 8 | H16: 3 | I16: 8 | J16: 10 | K16: 8 | L16: 11 | M16: 8 | N16: 7 | O16: 8 | Q16: {=TRANSPOSE(P17:P$24)} -> 2 | R16: 6 | S16: 11 | T16: 3 | U16: 6 | V16: 14 | W16: 13 | X16: 16
A17: EB | B17: 7 | C17: 4 | D17: 0 | E17: 9 | F17: 7 | G17: 13 | H17: 9 | I17: 2 | J17: 7 | K17: 7 | L17: 3 | M17: 21 | N17: 6 | O17: 11 | P17: 2 | R17: {=TRANSPOSE(Q18:Q$24)} -> 14 | S17: 6 | T17: 15 | U17: 6 | V17: 13 | W17: 8 | X17: 6
A18: AIAM-A | B18: 16 | C18: 13 | D18: 5 | E18: 13 | F18: 6 | G18: 4 | H18: 10 | I18: 6 | J18: 6 | K18: 6 | L18: 9 | M18: 7 | N18: 11 | O18: 16 | P18: 6 | Q18: 14 | S18: {=TRANSPOSE(R19:R$24)} -> 0 | T18: 16 | U18: 5 | V18: 10 | W18: 15 | X18: 0
A19: AIAM-B | B19: 13 | C19: 13 | D19: 6 | E19: 8 | F19: 7 | G19: 3 | H19: 4 | I19: 3 | J19: 3 | K19: 11 | L19: 4 | M19: 0 | N19: 7 | O19: 5 | P19: 11 | Q19: 6 | R19: 0 | T19: {=TRANSPOSE(S20:S$24)} -> 0 | U19: 28 | V19: 14 | W19: 8 | X19: 24
A20: SA-A | B20: 17 | C20: 5 | D20: 5 | E20: 15 | F20: 10 | G20: 3 | H20: 4 | I20: 8 | J20: 2 | K20: 14 | L20: 9 | M20: 3 | N20: 9 | O20: 8 | P20: 3 | Q20: 15 | R20: 16 | S20: 0 | U20: {=TRANSPOSE(T21:T$24)} -> 0 | V20: 11 | W20: 3 | X20: 14
A21: SA-B | B21: 9 | C21: 19 | D21: 5 | E21: 9 | F21: 3 | G21: 0 | H21: 5 | I21: 0 | J21: 5 | K21: 15 | L21: 7 | M21: 0 | N21: 7 | O21: 7 | P21: 6 | Q21: 6 | R21: 5 | S21: 28 | T21: 0 | V21: {=TRANSPOSE(U22:U$24)} -> 14 | W21: 12 | X21: 16
A22: CSM | B22: 8 | C22: 14 | D22: 5 | E22: 6 | F22: 2 | G22: 1 | H22: 8 | I22: 0 | J22: 5 | K22: 7 | L22: 10 | M22: 4 | N22: 4 | O22: 11 | P22: 14 | Q22: 13 | R22: 10 | S22: 14 | T22: 11 | U22: 14 | W22: {=TRANSPOSE(V23:V$24)} -> 14 | X22: 15
A23: EM | B23: 10 | C23: 14 | D23: 12 | E23: 13 | F23: 11 | G23: 0 | H23: 4 | I23: 8 | J23: 9 | K23: 3 | L23: 4 | M23: 10 | N23: 15 | O23: 15 | P23: 13 | Q23: 8 | R23: 15 | S23: 8 | T23: 3 | U23: 12 | V23: 14 | X23: {=TRANSPOSE(W24:W$24)} -> 10
A24: I4TS | B24: 14 | C24: 11 | D24: 5 | E24: 9 | F24: 7 | G24: 5 | H24: 5 | I24: 4 | J24: 11 | K24: 4 | L24: 5 | M24: 2 | N24: 10 | O24: 5 | P24: 16 | Q24: 6 | R24: 0 | S24: 24 | T24: 14 | U24: 16 | V24: 15 | W24: 10

Sheet Sample Sheet
A1: Student ID | B1: Student Name
A2: BA006-24 | B2: {=_xludf.XLOOKUP(A2,Batch_Data!$A$2:$A$438,Batch_Data!$B$2:$B$438)} -> #NAME?
A3: BA007-24 | B3: {=_xludf.XLOOKUP(A3,Batch_Data!$A$2:$A$438,Batch_Data!$B$2:$B$438)} -> #NAME?
A4: BA021-24 | B4: {=_xludf.XLOOKUP(A4,Batch_Data!$A$2:$A$438,Batch_Data!$B$2:$B$438)} -> #NAME?
A5: BA025-24 | B5: {=_xludf.XLOOKUP(A5,Batch_Data!$A$2:$A$438,Batch_Data!$B$2:$B$438)} -> #NAME?
A6: BA028-24 | B6: {=_xludf.XLOOKUP(A6,Batch_Data!$A$2:$A$438,Batch_Data!$B$2:$B$438)} -> #NAME?
A7: BA033-24 | B7: {=_xludf.XLOOKUP(A7,Batch_Data!$A$2:$A$438,Batch_Data!$B$2:$B$438)} -> #NAME?
A8: BA044-24 | B8: {=_xludf.XLOOKUP(A8,Batch_Data!$A$2:$A$438,Batch_Data!$B$2:$B$438)} -> #NAME?
A9: BA047-24 | B9: {=_xludf.XLOOKUP(A9,Batch_Data!$A$2:$A$438,Batch_Data!$B$2:$B$438)} -> #NAME?
A10: BA049-24 | B10: {=_xludf.XLOOKUP(A10,Batch_Data!$A$2:$A$438,Batch_Data!$B$2:$B$438)} -> #NAME?
A11: BA050-24 | B11: {=_xludf.XLOOKUP(A11,Batch_Data!$A$2:$A$438,Batch_Data!$B$2:$B$438)} -> #NAME?
A12: BA052-24 | B12: {=_xludf.XLOOKUP(A12,Batch_Data!$A$2:$A$438,Batch_Data!$B$2:$B$438)} -> #NAME?
A13: H002-24 | B13: {=_xludf.XLOOKUP(A13,Batch_Data!$A$2:$A$438,Batch_Data!$B$2:$B$438)} -> #NAME?
... A141: M262-24 | B141: {=_xludf.XLOOKUP(A141,Batch_Data!$A$2:$A$438,Batch_Data!$B$2:$B$438)} -> #NAME?
B142: {=_xludf.XLOOKUP(A142,Batch_Data!$A$2:$A$438,Batch_Data!$B$2:$B$438)} -> #NAME?
B143: {=_xludf.XLOOKUP(A143,Batch_Data!$A$2:$A$438,Batch_Data!$B$2:$B$438)} -> #NAME?
B144: {=_xludf.XLOOKUP(A144,Batch_Data!$A$2:$A$438,Batch_Data!$B$2:$B$438)} -> #NAME?
B145: {=_xludf.XLOOKUP(A145,Batch_Data!$A$2:$A$438,Batch_Data!$B$2:$B$438)} -> #NAME?
B146: {=_xludf.XLOOKUP(A146,Batch_Data!$A$2:$A$438,Batch_Data!$B$2:$B$438)} -> #NAME?
B147: {=_xludf.XLOOKUP(A147,Batch_Data!$A$2:$A$438,Batch_Data!$B$2:$B$438)} -> #NAME?
B148: {=_xludf.XLOOKUP(A148,Batch_Data!$A$2:$A$438,Batch_Data!$B$2:$B$438)} -> #NAME?
B149: {=_xludf.XLOOKUP(A149,Batch_Data!$A$2:$A$438,Batch_Data!$B$2:$B$438)} -> #NAME?
B150: {=_xludf.XLOOKUP(A150,Batch_Data!$A$2:$A$438,Batch_Data!$B$2:$B$438)} -> #NAME?
B151: {=_xludf.XLOOKUP(A151,Batch_Data!$A$2:$A$438,Batch_Data!$B$2:$B$438)} -> #NAME?
B152: {=_xludf.XLOOKUP(A152,Batch_Data!$A$2:$A$438,Batch_Data!$B$2:$B$438)} -> #NAME?
B153: {=_xludf.XLOOKUP(A153,Batch_Data!$A$2:$A$438,Batch_Data!$B$2:$B$438)} -> #NAME?
... B266: {=_xludf.XLOOKUP(A266,Batch_Data!$A$2:$A$438,Batch_Data!$B$2:$B$438)} -> #NAME?

Sheet Section Details
A1: Course Code | B1: Course Name | C1: Faculty | D1: Int vs Ext | E1: Session Count | F1: Section | G1: #Students
A2: FAISE01 | B2: Fintech (Digital Transformation in Finance) | C2: Prof Shumaila Fatima, Prof Gautam Pal | E2: 1-9; 10; 11-20 | F2: 2 | G2: 129
A3: HRECFAE01 | B3: Behavioural Economics and Decision-Making | C3: Prof. Tanusree Dutta, Prof. Amarendu Nandy, Prof. Poonam | D3: 13,7 | E3: 6,10,14,16,19; 1-5,11,15,20 ; 7-9,12-13,17-18 | F3: 2 | G3: 92
A4: HRISE01 | B4: The Art, Craft, and Science of Management: Learning through Classics and Best Collections | C4: Ambuj B. Anand,Manish Kumar, Guest Faculty | E4: 10,10, 2 | F4: 2 | G4: 106
A5: HRLAE01 | B5: Workplace Happiness: Science & Practice | C5: Prof. Tanusree Dutta, Prof. Allen Joshua George, Guest Faculty | E5: 2,6,9,11,17; 1,3-5,7,8,10,12-16,18; 19,20 | F5: 2 | G5: 117
A6: HRLAE03 | B6: Leadership Excellence Through Values : Wisdom from the Mahabharata | C6: Dr. Radha Yadav, Dr. Prasant Maurya, Dr. Ashish Pandey | D6: 15,5 | E6: 1-9,20; 10-14; 15-19 | F6: 1 | G6: 61
A7: HRLAEISE01 | B7: Film & the Firm: Visual Culture in Business Contexts | C7: Prof. Vikas Pathe, Prof. Ambuj B Anand, Prof. Manish Kumar, Prof. Gaurav M Marathe, Prof. George Joseph, Guest Faculty | D7: 18,2 | E7: 1-4,13-16; 17-18; 5-6,9-10; 7-8; 19-20; 11-12 | F7: 2 | G7: 140
A8: HRSEE01 | B8: Strategic HRM | C8: Prof. Rameshwar Shivadas Ture, Mr. Vaibhav Goel | D8: 15, 5 | E8: 1-9,15-20; 10-14 | F8: 1 | G8: 72
A9: HRSEE02 | B9: Strategic Career Management | C9: Prof. Rohit Kumar , Prof. Aditya Agrawal | E9: 3,10-13; 1,2,4-9,14-20 | F9: 2 | G9: 133
A10: ISSEE01 | B10: AI AND STRATEGY | C10: Prof Jang Bahadur Singh Prof. Santosh K Prusty | D10: 45881 | E10: 1-8, 9-20 | F10: 1 | G10: 70
A11: MKHRE01 | B11: Employer Branding | C11: Prof. Radha Yadav, Prof. Shweta Jha | E11: 1-10, 11-20 | F11: 1 | G11: 71
A12: MKISE01 | B12: AI Applications in Marketing | C12: Prof. Ankur Jha, Prof. Shweta Jha, Dr. Charu Jain and Ms.Deborah T. Joy | D12: 10,10 | E12: 1-5, 6-10, 11-15, 16-20 | F12: 2 | G12: 140
A13: MKISE02 | B13: SPORTS ANALYTICS | C13: Ambuj B Anand, R Vivekanand | D13: 45792 | E13: 5, 15 (Whatever is comfortable with VF) | F13: 2 | G13: 140
A14: MKISE03 | B14: Customer Success Management | C14: Prof Shilpi Saxena, Mr. Nishant Gaurav | D14: 15, 5 | E14: 1-15, 16-20 | F14: 1 | G14: 70
A15: MKSEE01 | B15: Entrepreneurial Marketing | C15: Prof. Satyam, Prof. Rohit Kumar,Mr. Avnish Anand | D15: 15, 5 | E15: 6-10,16-20; 1-5; 11-15 | F15: 1 | G15: 70
A16: OMISE01 | B16: Industry 4.0 in Transport Sector | C16: Prof.Krishna Kumar Dadsena, Prof. Sachin Bajaj, Prof. Reema Jogani, Prof. Shailabh Kumar Sahu | D16: 6,14 | E16: 6, 6, 4, 4 | F16: 1 | G16: 70
F17: =SUM(F2:F16) -> 23

Sheet Batch || Working
A1: S. No. | B1: Section | C1: Roll No | D1: Name | E1: Email ID | F1: #Courses | G1: Subject 1 | H1: Subject 2 | I1: Subject 3 | J1: Subject 4 | K1: Subject 5 | M1: Subject 1 | N1: Fintech (Digital Transformation in Finance) (A) | P1: {=TRANSPOSE(N1:N23)} -> Fintech (Digital Transformation in Finance) (A) | Q1: Fintech (Digital Transformation in Finance) (B) | R1: Behavioural Economics and Decision-Making (A) | S1: Behavioural Economics and Decision-Making (B) | T1: The Art, Craft, and Science of Management: Learning through Classics and Best Collections (A) | U1: The Art, Craft, and Science of Management: Learning through Classics and Best Collections (B) | V1: Workplace Happiness: Science & Practice (A) | W1: Workplace Happiness: Science & Practice (B) | X1: Leadership Excellence Through Values : Wisdom from the Mahabharata | Y1: Film & the Firm: Visual Culture in Business Contexts (A) | Z1: Film & the Firm: Visual Culture in Business Contexts (B) | AA1: Strategic HRM | AB1: Strategic Career Management (A) | AC1: Strategic Career Management (B) | AD1: AI AND STRATEGY | AE1: Employer Branding | AF1: AI Applications in Marketing (A) | AG1: AI Applications in Marketing (B) | AH1: SPORTS ANALYTICS (A) | AI1: SPORTS ANALYTICS (B) | AJ1: Customer Success Management | AK1: Entrepreneurial Marketing | AL1: Industry 4.0 in Transport Sector
A2: 1 | B2: A | C2: M001-24 | D2: Aakriti Priya | E2: aakriti.priya24m@iimranchi.ac.in | F2: =COUNTA(G2:K2) -> 5 | G2: =IFERROR(__xludf.DUMMYFUNCTION("INDEX(FILTER($P2:$AL2, $P2:$AL2 <> """"), 1)"),"Workplace Happiness: Science & Practice (A)") -> Workplace Happiness: Science & Practice (A) | H2: =IFERROR(__xludf.DUMMYFUNCTION("INDEX(FILTER($P2:$AL2, $P2:$AL2 <> """"), 2)"),"Strategic Career Management (A)") -> Strategic Career Management (A) | I2: =IFERROR(__xludf.DUMMYFUNCTION("INDEX(FILTER($P2:$AL2, $P2:$AL2 <> """"), 3)"),"Industry 4.0 in Transport Sector") -> Industry 4.0 in Transport Sector | J2: =IFERROR(__xludf.DUMMYFUNCTION("IFERROR(INDEX(FILTER($P2:$AL2, $P2:$AL2 <> """"), 4),)"),"") | K2: =IFERROR(__xludf.DUMMYFUNCTION("IFERROR(INDEX(FILTER($P2:$AL2, $P2:$AL2 <> """"), 5),)"),"") | M2: Subject 2 | N2: Fintech (Digital Transformation in Finance) (B) | P2: =IF(COUNTIF('Fintech-A'!$A:$A, $C2), P$1, "") | Q2: =IF(COUNTIF('Fintech-B'!$A:$A, $C2), Q$1, "") | R2: =IF(COUNTIF('BEDM-A'!$A:$A, $C2), R$1, "") | S2: =IF(COUNTIF('BEDM-B'!$A:$A, $C2), S$1, "") | T2: =IF(COUNTIF('Art-A'!$A:$A, $C2), T$1, "") | U2: =IF(COUNTIF('Art-B'!$A:$A, $C2), U$1, "") | V2: =IF(COUNTIF('WH-A'!$A:$A, $C2), V$1, "") -> Workplace Happiness: Science & Practice (A) | W2: =IF(COUNTIF('WH-B'!$A:$A, $C2), W$1, "") | X2: =IF(COUNTIF(LETV!$A:$A, $C2), X$1, "") | Y2: =IF(COUNTIF('Film&Firm-A'!$A:$A, $C2), Y$1, "") | Z2: =IF(COUNTIF('Film&Firm-B'!$A:$A, $C2), Z$1, "") | AA2: =IF(COUNTIF(SHRM!$A:$A, $C2), AA$1, "") | AB2: =IF(COUNTIF('SCM-A'!$A:$A, $C2), AB$1, "") -> Strategic Career Management (A) | AC2: =IF(COUNTIF('SCM-B'!$A:$A, $C2), AC$1, "") | AD2: =IF(COUNTIF(AIS!$A:$A, $C2), AD$1, "") | AE2: =IF(COUNTIF(EB!$A:$A, $C2), AE$1, "") | AF2: =IF(COUNTIF('AIAM-A'!$A:$A, $C2), AF$1, "") | AG2: =IF(COUNTIF('AIAM-B'!$A:$A, $C2), AG$1, "") | AH2: =IF(COUNTIF('SA-A'!$A:$A, $C2), AH$1, "") | AI2: =IF(COUNTIF('SA-B'!$A:$A, $C2), AI$1, "") | AJ2: =IF(COUNTIF(CSM!$A:$A, $C2), AJ$1, "") | AK2: =IF(COUNTIF(EM!$A:$A, $C2), AK$1, "") | AL2: =IF(COUNTIF(I4TS!$A:$A, $C2), AL$1, "") -> Industry 4.0 in Transport Sector
A3: 2 | B3: A | C3: M002-24 | D3: Aditya Kumar | E3: aditya.kumar24m@iimranchi.ac.in | F3: =COUNTA(G3:K3) -> 5 | G3: =IFERROR(__xludf.DUMMYFUNCTION("INDEX(FILTER($P3:$AL3, $P3:$AL3 <> """"), 1)"),"Strategic Career Management (B)") -> Strategic Career Management (B) | H3: =IFERROR(__xludf.DUMMYFUNCTION("INDEX(FILTER($P3:$AL3, $P3:$AL3 <> """"), 2)"),"AI AND STRATEGY") -> AI AND STRATEGY | I3: =IFERROR(__xludf.DUMMYFUNCTION("INDEX(FILTER($P3:$AL3, $P3:$AL3 <> """"), 3)"),"Entrepreneurial Marketing") -> Entrepreneurial Marketing | J3: =IFERROR(__xludf.DUMMYFUNCTION("IFERROR(INDEX(FILTER($P3:$AL3, $P3:$AL3 <> """"), 4),)"),"") | K3: =IFERROR(__xludf.DUMMYFUNCTION("IFERROR(INDEX(FILTER($P3:$AL3, $P3:$AL3 <> """"), 5),)"),"") | M3: Subject 3 | N3: Behavioural Economics and Decision-Making (A) | P3: =IF(COUNTIF('Fintech-A'!$A:$A, $C3), P$1, "") | Q3: =IF(COUNTIF('Fintech-B'!$A:$A, $C3), Q$1, "") | R3: =IF(COUNTIF('BEDM-A'!$A:$A, $C3), R$1, "") | S3: =IF(COUNTIF('BEDM-B'!$A:$A, $C3), S$1, "") | T3: =IF(COUNTIF('Art-A'!$A:$A, $C3), T$1, "") | U3: =IF(COUNTIF('Art-B'!$A:$A, $C3), U$1, "") | V3: =IF(COUNTIF('WH-A'!$A:$A, $C3), V$1, "") | W3: =IF(COUNTIF('WH-B'!$A:$A, $C3), W$1, "") | X3: =IF(COUNTIF(LETV!$A:$A, $C3), X$1, "") | Y3: =IF(COUNTIF('Film&Firm-A'!$A:$A, $C3), Y$1, "") | Z3: =IF(COUNTIF('Film&Firm-B'!$A:$A, $C3), Z$1, "") | AA3: =IF(COUNTIF(SHRM!$A:$A, $C3), AA$1, "") | AB3: =IF(COUNTIF('SCM-A'!$A:$A, $C3), AB$1, "") | AC3: =IF(COUNTIF('SCM-B'!$A:$A, $C3), AC$1, "") -> Strategic Career Management (B) | AD3: =IF(COUNTIF(AIS!$A:$A, $C3), AD$1, "") -> AI AND STRATEGY | AE3: =IF(COUNTIF(EB!$A:$A, $C3), AE$1, "") | AF3: =IF(COUNTIF('AIAM-A'!$A:$A, $C3), AF$1, "") | AG3: =IF(COUNTIF('AIAM-B'!$A:$A, $C3), AG$1, "") | AH3: =IF(COUNTIF('SA-A'!$A:$A, $C3), AH$1, "") | AI3: =IF(COUNTIF('SA-B'!$A:$A, $C3), AI$1, "") | AJ3: =IF(COUNTIF(CSM!$A:$A, $C3), AJ$1, "") | AK3: =IF(COUNTIF(EM!$A:$A, $C3), AK$1, "") -> Entrepreneurial Marketing | AL3: =IF(COUNTIF(I4TS!$A:$A, $C3), AL$1, "")
A4: 3 | B4: A | C4: M003-24 | D4: Akshay Vaishnav | E4: akshay.vaishnav24m@iimranchi.ac.in | F4: =COUNTA(G4:K4) -> 5 | G4: =IFERROR(__xludf.DUMMYFUNCTION("INDEX(FILTER($P4:$AL4, $P4:$AL4 <> """"), 1)"),"Fintech (Digital Transformation in Finance) (B)") -> Fintech (Digital Transformation in Finance) (B) | H4: =IFERROR(__xludf.DUMMYFUNCTION("INDEX(FILTER($P4:$AL4, $P4:$AL4 <> """"), 2)"),"AI AND STRATEGY") -> AI AND STRATEGY | I4: =IFERROR(__xludf.DUMMYFUNCTION("INDEX(FILTER($P4:$AL4, $P4:$AL4 <> """"), 3)"),"AI Applications in Marketing (B)") -> AI Applications in Marketing (B) | J4: =IFERROR(__xludf.DUMMYFUNCTION("IFERROR(INDEX(FILTER($P4:$AL4, $P4:$AL4 <> """"), 4),)"),"SPORTS ANALYTICS (B)") -> SPORTS ANALYTICS (B) | K4: =IFERROR(__xludf.DUMMYFUNCTION("IFERROR(INDEX(FILTER($P4:$AL4, $P4:$AL4 <> """"), 5),)"),"Entrepreneurial Marketing") -> Entrepreneurial Marketing | M4: Subject 4 | N4: Behavioural Economics and Decision-Making (B) | P4: =IF(COUNTIF('Fintech-A'!$A:$A, $C4), P$1, "") | Q4: =IF(COUNTIF('Fintech-B'!$A:$A, $C4), Q$1, "") -> Fintech (Digital Transformation in Finance) (B) | R4: =IF(COUNTIF('BEDM-A'!$A:$A, $C4), R$1, "") | S4: =IF(COUNTIF('BEDM-B'!$A:$A, $C4), S$1, "") | T4: =IF(COUNTIF('Art-A'!$A:$A, $C4), T$1, "") | U4: =IF(COUNTIF('Art-B'!$A:$A, $C4), U$1, "") | V4: =IF(COUNTIF('WH-A'!$A:$A, $C4), V$1, "") | W4: =IF(COUNTIF('WH-B'!$A:$A, $C4), W$1, "") | X4: =IF(COUNTIF(LETV!$A:$A, $C4), X$1, "") | Y4: =IF(COUNTIF('Film&Firm-A'!$A:$A, $C4), Y$1, "") | Z4: =IF(COUNTIF('Film&Firm-B'!$A:$A, $C4), Z$1, "") | AA4: =IF(COUNTIF(SHRM!$A:$A, $C4), AA$1, "") | AB4: =IF(COUNTIF('SCM-A'!$A:$A, $C4), AB$1, "") | AC4: =IF(COUNTIF('SCM-B'!$A:$A, $C4), AC$1, "") | AD4: =IF(COUNTIF(AIS!$A:$A, $C4), AD$1, "") -> AI AND STRATEGY | AE4: =IF(COUNTIF(EB!$A:$A, $C4), AE$1, "") | AF4: =IF(COUNTIF('AIAM-A'!$A:$A, $C4), AF$1, "") | AG4: =IF(COUNTIF('AIAM-B'!$A:$A, $C4), AG$1, "") -> AI Applications in Marketing (B) | AH4: =IF(COUNTIF('SA-A'!$A:$A, $C4), AH$1, "") | AI4: =IF(COUNTIF('SA-B'!$A:$A, $C4), AI$1, "") -> SPORTS ANALYTICS (B) | AJ4: =IF(COUNTIF(CSM!$A:$A, $C4), AJ$1, "") | AK4: =IF(COUNTIF(EM!$A:$A, $C4), AK$1, "") -> Entrepreneurial Marketing | AL4: =IF(COUNTIF(I4TS!$A:$A, $C4), AL$1, "")
A5: 4 | B5: A | C5: M004-24 | D5: Alok Pandey | E5: alok.pandey24m@iimranchi.ac.in | F5: =COUNTA(G5:K5) -> 5 | G5: =IFERROR(__xludf.DUMMYFUNCTION("INDEX(FILTER($P5:$AL5, $P5:$AL5 <> """"), 1)"),"The Art, Craft, and Science of Management: Learning through Classics and Best Collections (A)") -> The Art, Craft, and Science of Management: Learning through Classics and Best Collections (A) | H5: =IFERROR(__xludf.DUMMYFUNCTION("INDEX(FILTER($P5:$AL5, $P5:$AL5 <> """"), 2)"),"Employer Branding") -> Employer Branding | I5: =IFERROR(__xludf.DUMMYFUNCTION("INDEX(FILTER($P5:$AL5, $P5:$AL5 <> """"), 3)"),"SPORTS ANALYTICS (A)") -> SPORTS ANALYTICS (A) | J5: =IFERROR(__xludf.DUMMYFUNCTION("IFERROR(INDEX(FILTER($P5:$AL5, $P5:$AL5 <> """"), 4),)"),"") | K5: =IFERROR(__xludf.DUMMYFUNCTION("IFERROR(INDEX(FILTER($P5:$AL5, $P5:$AL5 <> """"), 5),)"),"") | M5: Subject 5 | N5: The Art, Craft, and Science of Management: Learning through Classics and Best Collections (A) | P5: =IF(COUNTIF('Fintech-A'!$A:$A, $C5), P$1, "") | Q5: =IF(COUNTIF('Fintech-B'!$A:$A, $C5), Q$1, "") | R5: =IF(COUNTIF('BEDM-A'!$A:$A, $C5), R$1, "") | S5: =IF(COUNTIF('BEDM-B'!$A:$A, $C5), S$1, "") | T5: =IF(COUNTIF('Art-A'!$A:$A, $C5), T$1, "") -> The Art, Craft, and Science of Management: Learning through Classics and Best Collections (A) | U5: =IF(COUNTIF('Art-B'!$A:$A, $C5), U$1, "") | V5: =IF(COUNTIF('WH-A'!$A:$A, $C5), V$1, "") | W5: =IF(COUNTIF('WH-B'!$A:$A, $C5), W$1, "") | X5: =IF(COUNTIF(LETV!$A:$A, $C5), X$1, "") | Y5: =IF(COUNTIF('Film&Firm-A'!$A:$A, $C5), Y$1, "") | Z5: =IF(COUNTIF('Film&Firm-B'!$A:$A, $C5), Z$1, "") | AA5: =IF(COUNTIF(SHRM!$A:$A, $C5), AA$1, "") | AB5: =IF(COUNTIF('SCM-A'!$A:$A, $C5), AB$1, "") | AC5: =IF(COUNTIF('SCM-B'!$A:$A, $C5), AC$1, "") | AD5: =IF(COUNTIF(AIS!$A:$A, $C5), AD$1, "") | AE5: =IF(COUNTIF(EB!$A:$A, $C5), AE$1, "") -> Employer Branding | AF5: =IF(COUNTIF('AIAM-A'!$A:$A, $C5), AF$1, "") | AG5: =IF(COUNTIF('AIAM-B'!$A:$A, $C5), AG$1, "") | AH5: =IF(COUNTIF('SA-A'!$A:$A, $C5), AH$1, "") -> SPORTS ANALYTICS (A) | AI5: =IF(COUNTIF('SA-B'!$A:$A, $C5), AI$1, "") | AJ5: =IF(COUNTIF(CSM!$A:$A, $C5), AJ$1, "") | AK5: =IF(COUNTIF(EM!$A:$A, $C5), AK$1, "") | AL5: =IF(COUNTIF(I4TS!$A:$A, $C5), AL$1, "")
A6: 5 | B6: A | C6: M005-24 | D6: Alwyn Tej Kumar Toppo | E6: alwyn.tejkumartoppo24m@iimranchi.ac.in | F6: =COUNTA(G6:K6) -> 5 | G6: =IFERROR(__xludf.DUMMYFUNCTION("INDEX(FILTER($P6:$AL6, $P6:$AL6 <> """"), 1)"),"Film & the Firm: Visual Culture in Business Contexts (A)") -> Film & the Firm: Visual Culture in Business Contexts (A) | H6: =IFERROR(__xludf.DUMMYFUNCTION("INDEX(FILTER($P6:$AL6, $P6:$AL6 <> """"), 2)"),"AI Applications in Marketing (A)") -> AI Applications in Marketing (A) | I6: =IFERROR(__xludf.DUMMYFUNCTION("INDEX(FILTER($P6:$AL6, $P6:$AL6 <> """"), 3)"),"SPORTS ANALYTICS (A)") -> SPORTS ANALYTICS (A) | J6: =IFERROR(__xludf.DUMMYFUNCTION("IFERROR(INDEX(FILTER($P6:$AL6, $P6:$AL6 <> """"), 4),)"),"Customer Success Management") -> Customer Success Management | K6: =IFERROR(__xludf.DUMMYFUNCTION("IFERROR(INDEX(FILTER($P6:$AL6, $P6:$AL6 <> """"), 5),)"),"Entrepreneurial Marketing") -> Entrepreneurial Marketing | M6: Subject 6 | N6: The Art, Craft, and Science of Management: Learning through Classics and Best Collections (B) | P6: =IF(COUNTIF('Fintech-A'!$A:$A, $C6), P$1, "") | Q6: =IF(COUNTIF('Fintech-B'!$A:$A, $C6), Q$1, "") | R6: =IF(COUNTIF('BEDM-A'!$A:$A, $C6), R$1, "") | S6: =IF(COUNTIF('BEDM-B'!$A:$A, $C6), S$1, "") | T6: =IF(COUNTIF('Art-A'!$A:$A, $C6), T$1, "") | U6: =IF(COUNTIF('Art-B'!$A:$A, $C6), U$1, "") | V6: =IF(COUNTIF('WH-A'!$A:$A, $C6), V$1, "") | W6: =IF(COUNTIF('WH-B'!$A:$A, $C6), W$1, "") | X6: =IF(COUNTIF(LETV!$A:$A, $C6), X$1, "") | Y6: =IF(COUNTIF('Film&Firm-A'!$A:$A, $C6), Y$1, "") -> Film & the Firm: Visual Culture in Business Contexts (A) | Z6: =IF(COUNTIF('Film&Firm-B'!$A:$A, $C6), Z$1, "") | AA6: =IF(COUNTIF(SHRM!$A:$A, $C6), AA$1, "") | AB6: =IF(COUNTIF('SCM-A'!$A:$A, $C6), AB$1, "") | AC6: =IF(COUNTIF('SCM-B'!$A:$A, $C6), AC$1, "") | AD6: =IF(COUNTIF(AIS!$A:$A, $C6), AD$1, "") | AE6: =IF(COUNTIF(EB!$A:$A, $C6), AE$1, "") | AF6: =IF(COUNTIF('AIAM-A'!$A:$A, $C6), AF$1, "") -> AI Applications in Marketing (A) | AG6: =IF(COUNTIF('AIAM-B'!$A:$A, $C6), AG$1, "") | AH6: =IF(COUNTIF('SA-A'!$A:$A, $C6), AH$1, "") -> SPORTS ANALYTICS (A) | AI6: =IF(COUNTIF('SA-B'!$A:$A, $C6), AI$1, "") | AJ6: =IF(COUNTIF(CSM!$A:$A, $C6), AJ$1, "") -> Customer Success Management | AK6: =IF(COUNTIF(EM!$A:$A, $C6), AK$1, "") -> Entrepreneurial Marketing | AL6: =IF(COUNTIF(I4TS!$A:$A, $C6), AL$1, "")
A7: 6 | B7: A | C7: M006-24 | D7: Ananya Chhabra | E7: ananya.chhabra24m@iimranchi.ac.in | F7: =COUNTA(G7:K7) -> 5 | G7: =IFERROR(__xludf.DUMMYFUNCTION("INDEX(FILTER($P7:$AL7, $P7:$AL7 <> """"), 1)"),"Leadership Excellence Through Values : Wisdom from the Mahabharata") -> Leadership Excellence Through Values : Wisdom from the Mahabharata | H7: =IFERROR(__xludf.DUMMYFUNCTION("INDEX(FILTER($P7:$AL7, $P7:$AL7 <> """"), 2)"),"AI AND STRATEGY") -> AI AND STRATEGY | I7: =IFERROR(__xludf.DUMMYFUNCTION("INDEX(FILTER($P7:$AL7, $P7:$AL7 <> """"), 3)"),"Industry 4.0 in Transport Sector") -> Industry 4.0 in Transport Sector | J7: =IFERROR(__xludf.DUMMYFUNCTION("IFERROR(INDEX(FILTER($P7:$AL7, $P7:$AL7 <> """"), 4),)"),"") | K7: =IFERROR(__xludf.DUMMYFUNCTION("IFERROR(INDEX(FILTER($P7:$AL7, $P7:$AL7 <> """"), 5),)"),"") | M7: Subject 7 | N7: Workplace Happiness: Science & Practice (A) | P7: =IF(COUNTIF('Fintech-A'!$A:$A, $C7), P$1, "") | Q7: =IF(COUNTIF('Fintech-B'!$A:$A, $C7), Q$1, "") | R7: =IF(COUNTIF('BEDM-A'!$A:$A, $C7), R$1, "") | S7: =IF(COUNTIF('BEDM-B'!$A:$A, $C7), S$1, "") | T7: =IF(COUNTIF('Art-A'!$A:$A, $C7), T$1, "") | U7: =IF(COUNTIF('Art-B'!$A:$A, $C7), U$1, "") | V7: =IF(COUNTIF('WH-A'!$A:$A, $C7), V$1, "") | W7: =IF(COUNTIF('WH-B'!$A:$A, $C7), W$1, "") | X7: =IF(COUNTIF(LETV!$A:$A, $C7), X$1, "") -> Leadership Excellence Through Values : Wisdom from the Mahabharata | Y7: =IF(COUNTIF('Film&Firm-A'!$A:$A, $C7), Y$1, "") | Z7: =IF(COUNTIF('Film&Firm-B'!$A:$A, $C7), Z$1, "") | AA7: =IF(COUNTIF(SHRM!$A:$A, $C7), AA$1, "") | AB7: =IF(COUNTIF('SCM-A'!$A:$A, $C7), AB$1, "") | AC7: =IF(COUNTIF('SCM-B'!$A:$A, $C7), AC$1, "") | AD7: =IF(COUNTIF(AIS!$A:$A, $C7), AD$1, "") -> AI AND STRATEGY | AE7: =IF(COUNTIF(EB!$A:$A, $C7), AE$1, "") | AF7: =IF(COUNTIF('AIAM-A'!$A:$A, $C7), AF$1, "") | AG7: =IF(COUNTIF('AIAM-B'!$A:$A, $C7), AG$1, "") | AH7: =IF(COUNTIF('SA-A'!$A:$A, $C7), AH$1, "") | AI7: =IF(COUNTIF('SA-B'!$A:$A, $C7), AI$1, "") | AJ7: =IF(COUNTIF(CSM!$A:$A, $C7), AJ$1, "") | AK7: =IF(COUNTIF(EM!$A:$A, $C7), AK$1, "") | AL7: =IF(COUNTIF(I4TS!$A:$A, $C7), AL$1, "") -> Industry 4.0 in Transport Sector
A8: 7 | B8: A | C8: M007-24 | D8: Anish Kumar | E8: anish.kumar24m@iimranchi.ac.in | F8: =COUNTA(G8:K8) -> 5 | G8: =IFERROR(__xludf.DUMMYFUNCTION("INDEX(FILTER($P8:$AL8, $P8:$AL8 <> """"), 1)"),"Fintech (Digital Transformation in Finance) (B)") -> Fintech (Digital Transformation in Finance) (B) | H8: =IFERROR(__xludf.DUMMYFUNCTION("INDEX(FILTER($P8:$AL8, $P8:$AL8 <> """"), 2)"),"Behavioural Economics and Decision-Making (B)") -> Behavioural Economics and Decision-Making (B) | I8: =IFERROR(__xludf.DUMMYFUNCTION("INDEX(FILTER($P8:$AL8, $P8:$AL8 <> """"), 3)"),"Film & the Firm: Visual Culture in Business Contexts (A)") -> Film & the Firm: Visual Culture in Business Contexts (A) | J8: =IFERROR(__xludf.DUMMYFUNCTION("IFERROR(INDEX(FILTER($P8:$AL8, $P8:$AL8 <> """"), 4),)"),"") | K8: =IFERROR(__xludf.DUMMYFUNCTION("IFERROR(INDEX(FILTER($P8:$AL8, $P8:$AL8 <> """"), 5),)"),"") | M8: Subject 8 | N8: Workplace Happiness: Science & Practice (B) | P8: =IF(COUNTIF('Fintech-A'!$A:$A, $C8), P$1, "") | Q8: =IF(COUNTIF('Fintech-B'!$A:$A, $C8), Q$1, "") -> Fintech (Digital Transformation in Finance) (B) | R8: =IF(COUNTIF('BEDM-A'!$A:$A, $C8), R$1, "") | S8: =IF(COUNTIF('BEDM-B'!$A:$A, $C8), S$1, "") -> Behavioural Economics and Decision-Making (B) | T8: =IF(COUNTIF('Art-A'!$A:$A, $C8), T$1, "") | U8: =IF(COUNTIF('Art-B'!$A:$A, $C8), U$1, "") | V8: =IF(COUNTIF('WH-A'!$A:$A, $C8), V$1, "") | W8: =IF(COUNTIF('WH-B'!$A:$A, $C8), W$1, "") | X8: =IF(COUNTIF(LETV!$A:$A, $C8), X$1, "") | Y8: =IF(COUNTIF('Film&Firm-A'!$A:$A, $C8), Y$1, "") -> Film & the Firm: Visual Culture in Business Contexts (A) | Z8: =IF(COUNTIF('Film&Firm-B'!$A:$A, $C8), Z$1, "") | AA8: =IF(COUNTIF(SHRM!$A:$A, $C8), AA$1, "") | AB8: =IF(COUNTIF('SCM-A'!$A:$A, $C8), AB$1, "") | AC8: =IF(COUNTIF('SCM-B'!$A:$A, $C8), AC$1, "") | AD8: =IF(COUNTIF(AIS!$A:$A, $C8), AD$1, "") | AE8: =IF(COUNTIF(EB!$A:$A, $C8), AE$1, "") | AF8: =IF(COUNTIF('AIAM-A'!$A:$A, $C8), AF$1, "") | AG8: =IF(COUNTIF('AIAM-B'!$A:$A, $C8), AG$1, "") | AH8: =IF(COUNTIF('SA-A'!$A:$A, $C8), AH$1, "") | AI8: =IF(COUNTIF('SA-B'!$A:$A, $C8), AI$1, "") | AJ8: =IF(COUNTIF(CSM!$A:$A, $C8), AJ$1, "") | AK8: =IF(COUNTIF(EM!$A:$A, $C8), AK$1, "") | AL8: =IF(COUNTIF(I4TS!$A:$A, $C8), AL$1, "")
A9: 8 | B9: A | C9: M010-24 | D9: Athulya Lal | E9: athulya.lal24m@iimranchi.ac.in | F9: =COUNTA(G9:K9) -> 5 | G9: =IFERROR(__xludf.DUMMYFUNCTION("INDEX(FILTER($P9:$AL9, $P9:$AL9 <> """"), 1)"),"Behavioural Economics and Decision-Making (B)") -> Behavioural Economics and Decision-Making (B) | H9: =IFERROR(__xludf.DUMMYFUNCTION("INDEX(FILTER($P9:$AL9, $P9:$AL9 <> """"), 2)"),"Leadership Excellence Through Values : Wisdom from the Mahabharata") -> Leadership Excellence Through Values : Wisdom from the Mahabharata | I9: =IFERROR(__xludf.DUMMYFUNCTION("INDEX(FILTER($P9:$AL9, $P9:$AL9 <> """"), 3)"),"Film & the Firm: Visual Culture in Business Contexts (A)") -> Film & the Firm: Visual Culture in Business Contexts (A) | J9: =IFERROR(__xludf.DUMMYFUNCTION("IFERROR(INDEX(FILTER($P9:$AL9, $P9:$AL9 <> """"), 4),)"),"") | K9: =IFERROR(__xludf.DUMMYFUNCTION("IFERROR(INDEX(FILTER($P9:$AL9, $P9:$AL9 <> """"), 5),)"),"") | M9: Subject 9 | N9: Leadership Excellence Through Values : Wisdom from the Mahabharata | P9: =IF(COUNTIF('Fintech-A'!$A:$A, $C9), P$1, "") | Q9: =IF(COUNTIF('Fintech-B'!$A:$A, $C9), Q$1, "") | R9: =IF(COUNTIF('BEDM-A'!$A:$A, $C9), R$1, "") | S9: =IF(COUNTIF('BEDM-B'!$A:$A, $C9), S$1, "") -> Behavioural Economics and Decision-Making (B) | T9: =IF(COUNTIF('Art-A'!$A:$A, $C9), T$1, "") | U9: =IF(COUNTIF('Art-B'!$A:$A, $C9), U$1, "") | V9: =IF(COUNTIF('WH-A'!$A:$A, $C9), V$1, "") | W9: =IF(COUNTIF('WH-B'!$A:$A, $C9), W$1, "") | X9: =IF(COUNTIF(LETV!$A:$A, $C9), X$1, "") -> Leadership Excellence Through Values : Wisdom from the Mahabharata | Y9: =IF(COUNTIF('Film&Firm-A'!$A:$A, $C9), Y$1, "") -> Film & the Firm: Visual Culture in Business Contexts (A) | Z9: =IF(COUNTIF('Film&Firm-B'!$A:$A, $C9), Z$1, "") | AA9: =IF(COUNTIF(SHRM!$A:$A, $C9), AA$1, "") | AB9: =IF(COUNTIF('SCM-A'!$A:$A, $C9), AB$1, "") | AC9: =IF(COUNTIF('SCM-B'!$A:$A, $C9), AC$1, "") | AD9: =IF(COUNTIF(AIS!$A:$A, $C9), AD$1, "") | AE9: =IF(COUNTIF(EB!$A:$A, $C9), AE$1, "") | AF9: =IF(COUNTIF('AIAM-A'!$A:$A, $C9), AF$1, "") | AG9: =IF(COUNTIF('AIAM-B'!$A:$A, $C9), AG$1, "") | AH9: =IF(COUNTIF('SA-A'!$A:$A, $C9), AH$1, "") | AI9: =IF(COUNTIF('SA-B'!$A:$A, $C9), AI$1, "") | AJ9: =IF(COUNTIF(CSM!$A:$A, $C9), AJ$1, "") | AK9: =IF(COUNTIF(EM!$A:$A, $C9), AK$1, "") | AL9: =IF(COUNTIF(I4TS!$A:$A, $C9), AL$1, "")
A10: 9 | B10: A | C10: M011-24 | D10: Charushi Darro | E10: charushi.darro24m@iimranchi.ac.in | F10: =COUNTA(G10:K10) -> 5 | G10: =IFERROR(__xludf.DUMMYFUNCTION("INDEX(FILTER($P10:$AL10, $P10:$AL10 <> """"), 1)"),"Workplace Happiness: Science & Practice (B)") -> Workplace Happiness: Science & Practice (B) | H10: =IFERROR(__xludf.DUMMYFUNCTION("INDEX(FILTER($P10:$AL10, $P10:$AL10 <> """"), 2)"),"Film & the Firm: Visual Culture in Business Contexts (A)") -> Film & the Firm: Visual Culture in Business Contexts (A) | I10: =IFERROR(__xludf.DUMMYFUNCTION("INDEX(FILTER($P10:$AL10, $P10:$AL10 <> """"), 3)"),"Strategic HRM") -> Strategic HRM | J10: =IFERROR(__xludf.DUMMYFUNCTION("IFERROR(INDEX(FILTER($P10:$AL10, $P10:$AL10 <> """"), 4),)"),"AI AND STRATEGY") -> AI AND STRATEGY | K10: =IFERROR(__xludf.DUMMYFUNCTION("IFERROR(INDEX(FILTER($P10:$AL10, $P10:$AL10 <> """"), 5),)"),"Entrepreneurial Marketing") -> Entrepreneurial Marketing | M10: Subject 10 | N10: Film & the Firm: Visual Culture in Business Contexts (A) | P10: =IF(COUNTIF('Fintech-A'!$A:$A, $C10), P$1, "") | Q10: =IF(COUNTIF('Fintech-B'!$A:$A, $C10), Q$1, "") | R10: =IF(COUNTIF('BEDM-A'!$A:$A, $C10), R$1, "") | S10: =IF(COUNTIF('BEDM-B'!$A:$A, $C10), S$1, "") | T10: =IF(COUNTIF('Art-A'!$A:$A, $C10), T$1, "") | U10: =IF(COUNTIF('Art-B'!$A:$A, $C10), U$1, "") | V10: =IF(COUNTIF('WH-A'!$A:$A, $C10), V$1, "") | W10: =IF(COUNTIF('WH-B'!$A:$A, $C10), W$1, "") -> Workplace Happiness: Science & Practice (B) | X10: =IF(COUNTIF(LETV!$A:$A, $C10), X$1, "") | Y10: =IF(COUNTIF('Film&Firm-A'!$A:$A, $C10), Y$1, "") -> Film & the Firm: Visual Culture in Business Contexts (A) | Z10: =IF(COUNTIF('Film&Firm-B'!$A:$A, $C10), Z$1, "") | AA10: =IF(COUNTIF(SHRM!$A:$A, $C10), AA$1, "") -> Strategic HRM | AB10: =IF(COUNTIF('SCM-A'!$A:$A, $C10), AB$1, "") | AC10: =IF(COUNTIF('SCM-B'!$A:$A, $C10), AC$1, "") | AD10: =IF(COUNTIF(AIS!$A:$A, $C10), AD$1, "") -> AI AND STRATEGY | AE10: =IF(COUNTIF(EB!$A:$A, $C10), AE$1, "") | AF10: =IF(COUNTIF('AIAM-A'!$A:$A, $C10), AF$1, "") | AG10: =IF(COUNTIF('AIAM-B'!$A:$A, $C10), AG$1, "") | AH10: =IF(COUNTIF('SA-A'!$A:$A, $C10), AH$1, "") | AI10: =IF(COUNTIF('SA-B'!$A:$A, $C10), AI$1, "") | AJ10: =IF(COUNTIF(CSM!$A:$A, $C10), AJ$1, "") | AK10: =IF(COUNTIF(EM!$A:$A, $C10), AK$1, "") -> Entrepreneurial Marketing | AL10: =IF(COUNTIF(I4TS!$A:$A, $C10), AL$1, "")
A11: 10 | B11: A | C11: M012-24 | D11: Chaudhari Mithilesh Ramdas | E11: chaudhari.mithileshramdas24m@iimranchi.ac.in | F11: =COUNTA(G11:K11) -> 5 | G11: =IFERROR(__xludf.DUMMYFUNCTION("INDEX(FILTER($P11:$AL11, $P11:$AL11 <> """"), 1)"),"AI AND STRATEGY") -> AI AND STRATEGY | H11: =IFERROR(__xludf.DUMMYFUNCTION("INDEX(FILTER($P11:$AL11, $P11:$AL11 <> """"), 2)"),"AI Applications in Marketing (B)") -> AI Applications in Marketing (B) | I11: =IFERROR(__xludf.DUMMYFUNCTION("INDEX(FILTER($P11:$AL11, $P11:$AL11 <> """"), 3)"),"Customer Success Management") -> Customer Success Management | J11: =IFERROR(__xludf.DUMMYFUNCTION("IFERROR(INDEX(FILTER($P11:$AL11, $P11:$AL11 <> """"), 4),)"),"") | K11: =IFERROR(__xludf.DUMMYFUNCTION("IFERROR(INDEX(FILTER($P11:$AL11, $P11:$AL11 <> """"), 5),)"),"") | M11: Subject 11 | N11: Film & the Firm: Visual Culture in Business Contexts (B) | P11: =IF(COUNTIF('Fintech-A'!$A:$A, $C11), P$1, "") | Q11: =IF(COUNTIF('Fintech-B'!$A:$A, $C11), Q$1, "") | R11: =IF(COUNTIF('BEDM-A'!$A:$A, $C11), R$1, "") | S11: =IF(COUNTIF('BEDM-B'!$A:$A, $C11), S$1, "") | T11: =IF(COUNTIF('Art-A'!$A:$A, $C11), T$1, "") | U11: =IF(COUNTIF('Art-B'!$A:$A, $C11), U$1, "") | V11: =IF(COUNTIF('WH-A'!$A:$A, $C11), V$1, "") | W11: =IF(COUNTIF('WH-B'!$A:$A, $C11), W$1, "") | X11: =IF(COUNTIF(LETV!$A:$A, $C11), X$1, "") | Y11: =IF(COUNTIF('Film&Firm-A'!$A:$A, $C11), Y$1, "") | Z11: =IF(COUNTIF('Film&Firm-B'!$A:$A, $C11), Z$1, "") | AA11: =IF(COUNTIF(SHRM!$A:$A, $C11), AA$1, "") | AB11: =IF(COUNTIF('SCM-A'!$A:$A, $C11), AB$1, "") | AC11: =IF(COUNTIF('SCM-B'!$A:$A, $C11), AC$1, "") | AD11: =IF(COUNTIF(AIS!$A:$A, $C11), AD$1, "") -> AI AND STRATEGY | AE11: =IF(COUNTIF(EB!$A:$A, $C11), AE$1, "") | AF11: =IF(COUNTIF('AIAM-A'!$A:$A, $C11), AF$1, "") | AG11: =IF(COUNTIF('AIAM-B'!$A:$A, $C11), AG$1, "") -> AI Applications in Marketing (B) | AH11: =IF(COUNTIF('SA-A'!$A:$A, $C11), AH$1, "") | AI11: =IF(COUNTIF('SA-B'!$A:$A, $C11), AI$1, "") | AJ11: =IF(COUNTIF(CSM!$A:$A, $C11), AJ$1, "") -> Customer Success Management | AK11: =IF(COUNTIF(EM!$A:$A, $C11), AK$1, "") | AL11: =IF(COUNTIF(I4TS!$A:$A, $C11), AL$1, "")
A12: 11 | B12: A | C12: M013-24 | D12: Chetna | E12: chetna.24m@iimranchi.ac.in | F12: =COUNTA(G12:K12) -> 5 | G12: =IFERROR(__xludf.DUMMYFUNCTION("INDEX(FILTER($P12:$AL12, $P12:$AL12 <> """"), 1)"),"Fintech (Digital Transformation in Finance) (B)") -> Fintech (Digital Transformation in Finance) (B) | H12: =IFERROR(__xludf.DUMMYFUNCTION("INDEX(FILTER($P12:$AL12, $P12:$AL12 <> """"), 2)"),"Film & the Firm: Visual Culture in Business Contexts (B)") -> Film & the Firm: Visual Culture in Business Contexts (B) | I12: =IFERROR(__xludf.DUMMYFUNCTION("INDEX(FILTER($P12:$AL12, $P12:$AL12 <> """"), 3)"),"Strategic Career Management (A)") -> Strategic Career Management (A) | J12: =IFERROR(__xludf.DUMMYFUNCTION("IFERROR(INDEX(FILTER($P12:$AL12, $P12:$AL12 <> """"), 4),)"),"AI Applications in Marketing (B)") -> AI Applications in Marketing (B) | K12: =IFERROR(__xludf.DUMMYFUNCTION("IFERROR(INDEX(FILTER($P12:$AL12, $P12:$AL12 <> """"), 5),)"),"SPORTS ANALYTICS (B)") -> SPORTS ANALYTICS (B) | M12: Subject 12 | N12: Strategic HRM | P12: =IF(COUNTIF('Fintech-A'!$A:$A, $C12), P$1, "") | Q12: =IF(COUNTIF('Fintech-B'!$A:$A, $C12), Q$1, "") -> Fintech (Digital Transformation in Finance) (B) | R12: =IF(COUNTIF('BEDM-A'!$A:$A, $C12), R$1, "") | S12: =IF(COUNTIF('BEDM-B'!$A:$A, $C12), S$1, "") | T12: =IF(COUNTIF('Art-A'!$A:$A, $C12), T$1, "") | U12: =IF(COUNTIF('Art-B'!$A:$A, $C12), U$1, "") | V12: =IF(COUNTIF('WH-A'!$A:$A, $C12), V$1, "") | W12: =IF(COUNTIF('WH-B'!$A:$A, $C12), W$1, "") | X12: =IF(COUNTIF(LETV!$A:$A, $C12), X$1, "") | Y12: =IF(COUNTIF('Film&Firm-A'!$A:$A, $C12), Y$1, "") | Z12: =IF(COUNTIF('Film&Firm-B'!$A:$A, $C12), Z$1, "") -> Film & the Firm: Visual Culture in Business Contexts (B) | AA12: =IF(COUNTIF(SHRM!$A:$A, $C12), AA$1, "") | AB12: =IF(COUNTIF('SCM-A'!$A:$A, $C12), AB$1, "") -> Strategic Career Management (A) | AC12: =IF(COUNTIF('SCM-B'!$A:$A, $C12), AC$1, "") | AD12: =IF(COUNTIF(AIS!$A:$A, $C12), AD$1, "") | AE12: =IF(COUNTIF(EB!$A:$A, $C12), AE$1, "") | AF12: =IF(COUNTIF('AIAM-A'!$A:$A, $C12), AF$1, "") | AG12: =IF(COUNTIF('AIAM-B'!$A:$A, $C12), AG$1, "") -> AI Applications in Marketing (B) | AH12: =IF(COUNTIF('SA-A'!$A:$A, $C12), AH$1, "") | AI12: =IF(COUNTIF('SA-B'!$A:$A, $C12), AI$1, "") -> SPORTS ANALYTICS (B) | AJ12: =IF(COUNTIF(CSM!$A:$A, $C12), AJ$1, "") | AK12: =IF(COUNTIF(EM!$A:$A, $C12), AK$1, "") | AL12: =IF(COUNTIF(I4TS!$A:$A, $C12), AL$1, "")
A13: 12 | B13: A | C13: M014-24 | D13: Devangi Mohan Bhamare | E13: devangi.mohanbhamare24m@iimranchi.ac.in | F13: =COUNTA(G13:K13) -> 5 | G13: =IFERROR(__xludf.DUMMYFUNCTION("INDEX(FILTER($P13:$AL13, $P13:$AL13 <> """"), 1)"),"Behavioural Economics and Decision-Making (A)") -> Behavioural Economics and Decision-Making (A) | H13: =IFERROR(__xludf.DUMMYFUNCTION("INDEX(FILTER($P13:$AL13, $P13:$AL13 <> """"), 2)"),"Film & the Firm: Visual Culture in Business Contexts (B)") -> Film & the Firm: Visual Culture in Business Contexts (B) | I13: =IFERROR(__xludf.DUMMYFUNCTION("INDEX(FILTER($P13:$AL13, $P13:$AL13 <> """"), 3)"),"AI AND STRATEGY") -> AI AND STRATEGY | J13: =IFERROR(__xludf.DUMMYFUNCTION("IFERROR(INDEX(FILTER($P13:$AL13, $P13:$AL13 <> """"), 4),)"),"") | K13: =IFERROR(__xludf.DUMMYFUNCTION("IFERROR(INDEX(FILTER($P13:$AL13, $P13:$AL13 <> """"), 5),)"),"") | M13: Subject 13 | N13: Strategic Career Management (A) | P13: =IF(COUNTIF('Fintech-A'!$A:$A, $C13), P$1, "") | Q13: =IF(COUNTIF('Fintech-B'!$A:$A, $C13), Q$1, "") | R13: =IF(COUNTIF('BEDM-A'!$A:$A, $C13), R$1, "") -> Behavioural Economics and Decision-Making (A) | S13: =IF(COUNTIF('BEDM-B'!$A:$A, $C13), S$1, "") | T13: =IF(COUNTIF('Art-A'!$A:$A, $C13), T$1, "") | U13: =IF(COUNTIF('Art-B'!$A:$A, $C13), U$1, "") | V13: =IF(COUNTIF('WH-A'!$A:$A, $C13), V$1, "") | W13: =IF(COUNTIF('WH-B'!$A:$A, $C13), W$1, "") | X13: =IF(COUNTIF(LETV!$A:$A, $C13), X$1, "") | Y13: =IF(COUNTIF('Film&Firm-A'!$A:$A, $C13), Y$1, "") | Z13: =IF(COUNTIF('Film&Firm-B'!$A:$A, $C13), Z$1, "") -> Film & the Firm: Visual Culture in Business Contexts (B) | AA13: =IF(COUNTIF(SHRM!$A:$A, $C13), AA$1, "") | AB13: =IF(COUNTIF('SCM-A'!$A:$A, $C13), AB$1, "") | AC13: =IF(COUNTIF('SCM-B'!$A:$A, $C13), AC$1, "") | AD13: =IF(COUNTIF(AIS!$A:$A, $C13), AD$1, "") -> AI AND STRATEGY | AE13: =IF(COUNTIF(EB!$A:$A, $C13), AE$1, "") | AF13: =IF(COUNTIF('AIAM-A'!$A:$A, $C13), AF$1, "") | AG13: =IF(COUNTIF('AIAM-B'!$A:$A, $C13), AG$1, "") | AH13: =IF(COUNTIF('SA-A'!$A:$A, $C13), AH$1, "") | AI13: =IF(COUNTIF('SA-B'!$A:$A, $C13), AI$1, "") | AJ13: =IF(COUNTIF(CSM!$A:$A, $C13), AJ$1, "") | AK13: =IF(COUNTIF(EM!$A:$A, $C13), AK$1, "") | AL13: =IF(COUNTIF(I4TS!$A:$A, $C13), AL$1, "")
A14: 13 | B14: A | C14: M015-24 | D14: Dheeraj Kashyap | E14: dheeraj.kashyap24m@iimranchi.ac.in | F14: =COUNTA(G14:K14) -> 5 | G14: =IFERROR(__xludf.DUMMYFUNCTION("INDEX(FILTER($P14:$AL14, $P14:$AL14 <> """"), 1)"),"Fintech (Digital Transformation in Finance) (B)") -> Fintech (Digital Transformation in Finance) (B) | H14: =IFERROR(__xludf.DUMMYFUNCTION("INDEX(FILTER($P14:$AL14, $P14:$AL14 <> """"), 2)"),"Workplace Happiness: Science & Practice (B)") -> Workplace Happiness: Science & Practice (B) | I14: =IFERROR(__xludf.DUMMYFUNCTION("INDEX(FILTER($P14:$AL14, $P14:$AL14 <> """"), 3)"),"AI Applications in Marketing (A)") -> AI Applications in Marketing (A) | J14: =IFERROR(__xludf.DUMMYFUNCTION("IFERROR(INDEX(FILTER($P14:$AL14, $P14:$AL14 <> """"), 4),)"),"") | K14: =IFERROR(__xludf.DUMMYFUNCTION("IFERROR(INDEX(FILTER($P14:$AL14, $P14:$AL14 <> """"), 5),)"),"") | M14: Subject 14 | N14: Strategic Career Management (B) | P14: =IF(COUNTIF('Fintech-A'!$A:$A, $C14), P$1, "") | Q14: =IF(COUNTIF('Fintech-B'!$A:$A, $C14), Q$1, "") -> Fintech (Digital Transformation in Finance) (B) | R14: =IF(COUNTIF('BEDM-A'!$A:$A, $C14), R$1, "") | S14: =IF(COUNTIF('BEDM-B'!$A:$A, $C14), S$1, "") | T14: =IF(COUNTIF('Art-A'!$A:$A, $C14), T$1, "") | U14: =IF(COUNTIF('Art-B'!$A:$A, $C14), U$1, "") | V14: =IF(COUNTIF('WH-A'!$A:$A, $C14), V$1, "") | W14: =IF(COUNTIF('WH-B'!$A:$A, $C14), W$1, "") -> Workplace Happiness: Science & Practice (B) | X14: =IF(COUNTIF(LETV!$A:$A, $C14), X$1, "") | Y14: =IF(COUNTIF('Film&Firm-A'!$A:$A, $C14), Y$1, "") | Z14: =IF(COUNTIF('Film&Firm-B'!$A:$A, $C14), Z$1, "") | AA14: =IF(COUNTIF(SHRM!$A:$A, $C14), AA$1, "") | AB14: =IF(COUNTIF('SCM-A'!$A:$A, $C14), AB$1, "") | AC14: =IF(COUNTIF('SCM-B'!$A:$A, $C14), AC$1, "") | AD14: =IF(COUNTIF(AIS!$A:$A, $C14), AD$1, "") | AE14: =IF(COUNTIF(EB!$A:$A, $C14), AE$1, "") | AF14: =IF(COUNTIF('AIAM-A'!$A:$A, $C14), AF$1, "") -> AI Applications in Marketing (A) | AG14: =IF(COUNTIF('AIAM-B'!$A:$A, $C14), AG$1, "") | AH14: =IF(COUNTIF('SA-A'!$A:$A, $C14), AH$1, "") | AI14: =IF(COUNTIF('SA-B'!$A:$A, $C14), AI$1, "") | AJ14: =IF(COUNTIF(CSM!$A:$A, $C14), AJ$1, "") | AK14: =IF(COUNTIF(EM!$A:$A, $C14), AK$1, "") | AL14: =IF(COUNTIF(I4TS!$A:$A, $C14), AL$1, "")
